Workbook

Sheet Summary
B2: DBM Portal — Cost vs Revenue Snapshot
B3: Steady-state at full Phase 7. Monthly USD. Build cost excluded; future city integration noted below.
B5: Tier | C5: Monthly Cost | D5: Monthly Revenue | E5: Net Monthly | F5: Net Annual | G5: Margin %
B6: A. Pilot (30 MAU) | C6: =Costing!I6 -> 204 | D6: =Revenue!I27 -> 1950 | E6: =D6-C6 -> 1746 | F6: =E6*12 -> 20952 | G6: =IFERROR(E6/D6,"") -> 0.89538462
B7: B. Small (500 MAU) | C7: =Costing!I7 -> 1315 | D7: =Revenue!I28 -> 37000 | E7: =D7-C7 -> 35685 | F7: =E7*12 -> 428220 | G7: =IFERROR(E7/D7,"") -> 0.96445946
B8: C. Medium (4K MAU) | C8: =Costing!I8 -> 7369 | D8: =Revenue!I29 -> 350000 | E8: =D8-C8 -> 342631 | F8: =E8*12 -> 4111572 | G8: =IFERROR(E8/D8,"") -> 0.97894571
B9: D. Large (20K MAU) | C9: =Costing!I9 -> 27339 | D9: =Revenue!I30 -> 1750000 | E9: =D9-C9 -> 1722661 | F9: =E9*12 -> 20671932 | G9: =IFERROR(E9/D9,"") -> 0.98437771
B10: E. Viral (100K MAU) | C10: =Costing!I10 -> 117525 | D10: =Revenue!I31 -> 8650000 | E10: =D10-C10 -> 8532475 | F10: =E10*12 -> 102389700 | G10: =IFERROR(E10/D10,"") -> 0.98641329
B12: Revenue Streams
B13: Subscription ($100/pro/mo) | C13: Paying pros pay monthly. Active P3+ (once compare/finalize delivers value).
B14: Transaction take rate (4%) | C14: 4% of signed contract value. Active P4+ (e-sign live).
B15: Lead fees ($25/qualified lead) | C15: Charged per qualified lead delivered. Active P2+.
B17: Future Scope (not costed)
B18: City permit & building rules | C18: Planned integration with municipal APIs for permit/license lookup and building-code rules. Adds per-city onboarding cost + possible API fees. Excluded from this model.
B19: Build / one-time engineering | C19: Build cost, headcount, marketing, Stripe Connect passthrough fees, and taxes are all excluded per request.

Sheet Assumptions
B2: DBM Portal — Subscription Costing & Revenue Model
B3: Date: 2026-06-03 | Hosting cost = optimized Claude, Render baseline, headcount excluded
B5: Customer Tier Assumptions
B6: Metric | C6: A. Pilot | D6: B. Small | E6: C. Medium | F6: D. Large | G6: E. Viral
B7: Total registered users | C7: 50 | D7: 1000 | E7: 10000 | F7: 50000 | G7: 250000
B8: Monthly active users (MAU) | C8: 30 | D8: 500 | E8: 4000 | F8: 20000 | G8: 100000
B9: Paying pros (subscription) | C9: 5 | D9: 80 | E9: 600 | F9: 3000 | G9: 14000
B10: Contracts brokered / month | C10: 2 | D10: 40 | E10: 400 | F10: 2000 | G10: 10000
B11: Avg contract value ($) | C11: 15000 | D11: 15000 | E11: 15000 | F11: 15000 | G11: 15000
B12: Qualified leads delivered / mo | C12: 10 | D12: 200 | E12: 2000 | F12: 10000 | G12: 50000
B15: Revenue Model Assumptions
B16: Subscription price per paying pro / month ($) | C16: 100
B17: Transaction take rate on contracts (%) | C17: 0.04
B18: Lead fee per qualified lead ($) | C18: 25
B19: Homeowner price (free) | C19: 0
B22: Excluded from this model
B23: • Build / one-time engineering cost (per user request)
B30: Phase definitions (per DBM-website-app-development.xlsx)
B31: P1 | C31: Find the required contact (search, directory, profiles)
B32: P2 | C32: Get bids (bid forms, scope upload, AI scan)
B33: P3 | C33: Compare and finalize bids (comparison tools, normalization)
B34: P4 | C34: Sign Contract / Agreement (e-sign, autofill, legal docs)
B35: P5 | C35: Execute Contract (schedule, budget, RFI, payments, progress)
B36: P6 | C36: Close Contract (punchlists, lien releases)
B37: P7 | C37: Reviews / testimonials / lessons learnt

Sheet Costing
B2: Hosting + Operating Cost — Monthly USD
B3: Cumulative cost if you've shipped through that phase. Optimized Claude. Build cost excluded.
B5: Customer Tier | C5: P1 | D5: P2 | E5: P3 | F5: P4 | G5: P5 | H5: P6 | I5: P7
B6: A. Pilot (30 MAU) | C6: 30 | D6: 35 | E6: 43 | F6: 73 | G6: 163 | H6: 172 | I6: 204
B7: B. Small (500 MAU) | C7: 324 | D7: 384 | E7: 504 | F7: 658 | G7: 1012 | H7: 1108 | I7: 1315
B8: C. Medium (4K MAU) | C8: 1980 | D8: 2451 | E8: 3371 | F8: 4092 | G8: 5944 | H8: 6419 | I8: 7369
B9: D. Large (20K MAU) | C9: 7018 | D9: 9282 | E9: 13772 | F9: 16290 | G9: 22639 | H9: 24369 | I9: 27339
B10: E. Viral (100K MAU) | C10: 28426 | D10: 39477 | E10: 61677 | F10: 72275 | G10: 97275 | H10: 104125 | I10: 117525
B13: Annualized (×12)
B14: Customer Tier | C14: P1 | D14: P2 | E14: P3 | F14: P4 | G14: P5 | H14: P6 | I14: P7
B15: A. Pilot (30 MAU) | C15: =C6*12 -> 360 | D15: =D6*12 -> 420 | E15: =E6*12 -> 516 | F15: =F6*12 -> 876 | G15: =G6*12 -> 1956 | H15: =H6*12 -> 2064 | I15: =I6*12 -> 2448
B16: B. Small (500 MAU) | C16: =C7*12 -> 3888 | D16: =D7*12 -> 4608 | E16: =E7*12 -> 6048 | F16: =F7*12 -> 7896 | G16: =G7*12 -> 12144 | H16: =H7*12 -> 13296 | I16: =I7*12 -> 15780
B17: C. Medium (4K MAU) | C17: =C8*12 -> 23760 | D17: =D8*12 -> 29412 | E17: =E8*12 -> 40452 | F17: =F8*12 -> 49104 | G17: =G8*12 -> 71328 | H17: =H8*12 -> 77028 | I17: =I8*12 -> 88428
B18: D. Large (20K MAU) | C18: =C9*12 -> 84216 | D18: =D9*12 -> 111384 | E18: =E9*12 -> 165264 | F18: =F9*12 -> 195480 | G18: =G9*12 -> 271668 | H18: =H9*12 -> 292428 | I18: =I9*12 -> 328068
B19: E. Viral (100K MAU) | C19: =C10*12 -> 341112 | D19: =D10*12 -> 473724 | E19: =E10*12 -> 740124 | F19: =F10*12 -> 867300 | G19: =G10*12 -> 1167300 | H19: =H10*12 -> 1249500 | I19: =I10*12 -> 1410300
B22: Cost per MAU / month
B23: Customer Tier | C23: P1 | D23: P2 | E23: P3 | F23: P4 | G23: P5 | H23: P6 | I23: P7
B24: A. Pilot (30 MAU) | C24: =C6/Assumptions!C8 -> 1 | D24: =D6/Assumptions!C8 -> 1.1666667 | E24: =E6/Assumptions!C8 -> 1.4333333 | F24: =F6/Assumptions!C8 -> 2.4333333 | G24: =G6/Assumptions!C8 -> 5.4333333 | H24: =H6/Assumptions!C8 -> 5.7333333 | I24: =I6/Assumptions!C8 -> 6.8
B25: B. Small (500 MAU) | C25: =C7/Assumptions!D8 -> 0.648 | D25: =D7/Assumptions!D8 -> 0.768 | E25: =E7/Assumptions!D8 -> 1.008 | F25: =F7/Assumptions!D8 -> 1.316 | G25: =G7/Assumptions!D8 -> 2.024 | H25: =H7/Assumptions!D8 -> 2.216 | I25: =I7/Assumptions!D8 -> 2.63
B26: C. Medium (4K MAU) | C26: =C8/Assumptions!E8 -> 0.495 | D26: =D8/Assumptions!E8 -> 0.61275 | E26: =E8/Assumptions!E8 -> 0.84275 | F26: =F8/Assumptions!E8 -> 1.023 | G26: =G8/Assumptions!E8 -> 1.486 | H26: =H8/Assumptions!E8 -> 1.60475 | I26: =I8/Assumptions!E8 -> 1.84225
B27: D. Large (20K MAU) | C27: =C9/Assumptions!F8 -> 0.3509 | D27: =D9/Assumptions!F8 -> 0.4641 | E27: =E9/Assumptions!F8 -> 0.6886 | F27: =F9/Assumptions!F8 -> 0.8145 | G27: =G9/Assumptions!F8 -> 1.13195 | H27: =H9/Assumptions!F8 -> 1.21845 | I27: =I9/Assumptions!F8 -> 1.36695
B28: E. Viral (100K MAU) | C28: =C10/Assumptions!G8 -> 0.28426 | D28: =D10/Assumptions!G8 -> 0.39477 | E28: =E10/Assumptions!G8 -> 0.61677 | F28: =F10/Assumptions!G8 -> 0.72275 | G28: =G10/Assumptions!G8 -> 0.97275 | H28: =H10/Assumptions!G8 -> 1.04125 | I28: =I10/Assumptions!G8 -> 1.17525

Sheet Revenue
B2: Revenue Model — Monthly USD by Tier × Phase
B3: Three streams: Subscription (P3+), Transaction take rate (P4+), Lead fees (P2+). Build cost excluded.
B5: 1. Subscription Revenue ($/mo) | C5: P1 | D5: P2 | E5: P3 | F5: P4 | G5: P5 | H5: P6 | I5: P7
B6: A. Pilot (30 MAU) | C6: =Assumptions!C9*Assumptions!$C$16*0 -> 0 | D6: =Assumptions!C9*Assumptions!$C$16*0 -> 0 | E6: =Assumptions!C9*Assumptions!$C$16*1 -> 500 | F6: =Assumptions!C9*Assumptions!$C$16*1 -> 500 | G6: =Assumptions!C9*Assumptions!$C$16*1 -> 500 | H6: =Assumptions!C9*Assumptions!$C$16*1 -> 500 | I6: =Assumptions!C9*Assumptions!$C$16*1 -> 500
B7: B. Small (500 MAU) | C7: =Assumptions!D9*Assumptions!$C$16*0 -> 0 | D7: =Assumptions!D9*Assumptions!$C$16*0 -> 0 | E7: =Assumptions!D9*Assumptions!$C$16*1 -> 8000 | F7: =Assumptions!D9*Assumptions!$C$16*1 -> 8000 | G7: =Assumptions!D9*Assumptions!$C$16*1 -> 8000 | H7: =Assumptions!D9*Assumptions!$C$16*1 -> 8000 | I7: =Assumptions!D9*Assumptions!$C$16*1 -> 8000
B8: C. Medium (4K MAU) | C8: =Assumptions!E9*Assumptions!$C$16*0 -> 0 | D8: =Assumptions!E9*Assumptions!$C$16*0 -> 0 | E8: =Assumptions!E9*Assumptions!$C$16*1 -> 60000 | F8: =Assumptions!E9*Assumptions!$C$16*1 -> 60000 | G8: =Assumptions!E9*Assumptions!$C$16*1 -> 60000 | H8: =Assumptions!E9*Assumptions!$C$16*1 -> 60000 | I8: =Assumptions!E9*Assumptions!$C$16*1 -> 60000
B9: D. Large (20K MAU) | C9: =Assumptions!F9*Assumptions!$C$16*0 -> 0 | D9: =Assumptions!F9*Assumptions!$C$16*0 -> 0 | E9: =Assumptions!F9*Assumptions!$C$16*1 -> 300000 | F9: =Assumptions!F9*Assumptions!$C$16*1 -> 300000 | G9: =Assumptions!F9*Assumptions!$C$16*1 -> 300000 | H9: =Assumptions!F9*Assumptions!$C$16*1 -> 300000 | I9: =Assumptions!F9*Assumptions!$C$16*1 -> 300000
B10: E. Viral (100K MAU) | C10: =Assumptions!G9*Assumptions!$C$16*0 -> 0 | D10: =Assumptions!G9*Assumptions!$C$16*0 -> 0 | E10: =Assumptions!G9*Assumptions!$C$16*1 -> 1400000 | F10: =Assumptions!G9*Assumptions!$C$16*1 -> 1400000 | G10: =Assumptions!G9*Assumptions!$C$16*1 -> 1400000 | H10: =Assumptions!G9*Assumptions!$C$16*1 -> 1400000 | I10: =Assumptions!G9*Assumptions!$C$16*1 -> 1400000
B12: 2. Transaction Take Rate ($/mo) | C12: P1 | D12: P2 | E12: P3 | F12: P4 | G12: P5 | H12: P6 | I12: P7
B13: A. Pilot (30 MAU) | C13: =Assumptions!C10*Assumptions!C11*Assumptions!$C$17*0 -> 0 | D13: =Assumptions!C10*Assumptions!C11*Assumptions!$C$17*0 -> 0 | E13: =Assumptions!C10*Assumptions!C11*Assumptions!$C$17*0 -> 0 | F13: =Assumptions!C10*Assumptions!C11*Assumptions!$C$17*1 -> 1200 | G13: =Assumptions!C10*Assumptions!C11*Assumptions!$C$17*1 -> 1200 | H13: =Assumptions!C10*Assumptions!C11*Assumptions!$C$17*1 -> 1200 | I13: =Assumptions!C10*Assumptions!C11*Assumptions!$C$17*1 -> 1200
B14: B. Small (500 MAU) | C14: =Assumptions!D10*Assumptions!D11*Assumptions!$C$17*0 -> 0 | D14: =Assumptions!D10*Assumptions!D11*Assumptions!$C$17*0 -> 0 | E14: =Assumptions!D10*Assumptions!D11*Assumptions!$C$17*0 -> 0 | F14: =Assumptions!D10*Assumptions!D11*Assumptions!$C$17*1 -> 24000 | G14: =Assumptions!D10*Assumptions!D11*Assumptions!$C$17*1 -> 24000 | H14: =Assumptions!D10*Assumptions!D11*Assumptions!$C$17*1 -> 24000 | I14: =Assumptions!D10*Assumptions!D11*Assumptions!$C$17*1 -> 24000
B15: C. Medium (4K MAU) | C15: =Assumptions!E10*Assumptions!E11*Assumptions!$C$17*0 -> 0 | D15: =Assumptions!E10*Assumptions!E11*Assumptions!$C$17*0 -> 0 | E15: =Assumptions!E10*Assumptions!E11*Assumptions!$C$17*0 -> 0 | F15: =Assumptions!E10*Assumptions!E11*Assumptions!$C$17*1 -> 240000 | G15: =Assumptions!E10*Assumptions!E11*Assumptions!$C$17*1 -> 240000 | H15: =Assumptions!E10*Assumptions!E11*Assumptions!$C$17*1 -> 240000 | I15: =Assumptions!E10*Assumptions!E11*Assumptions!$C$17*1 -> 240000
B16: D. Large (20K MAU) | C16: =Assumptions!F10*Assumptions!F11*Assumptions!$C$17*0 -> 0 | D16: =Assumptions!F10*Assumptions!F11*Assumptions!$C$17*0 -> 0 | E16: =Assumptions!F10*Assumptions!F11*Assumptions!$C$17*0 -> 0 | F16: =Assumptions!F10*Assumptions!F11*Assumptions!$C$17*1 -> 1200000 | G16: =Assumptions!F10*Assumptions!F11*Assumptions!$C$17*1 -> 1200000 | H16: =Assumptions!F10*Assumptions!F11*Assumptions!$C$17*1 -> 1200000 | I16: =Assumptions!F10*Assumptions!F11*Assumptions!$C$17*1 -> 1200000
B17: E. Viral (100K MAU) | C17: =Assumptions!G10*Assumptions!G11*Assumptions!$C$17*0 -> 0 | D17: =Assumptions!G10*Assumptions!G11*Assumptions!$C$17*0 -> 0 | E17: =Assumptions!G10*Assumptions!G11*Assumptions!$C$17*0 -> 0 | F17: =Assumptions!G10*Assumptions!G11*Assumptions!$C$17*1 -> 6000000 | G17: =Assumptions!G10*Assumptions!G11*Assumptions!$C$17*1 -> 6000000 | H17: =Assumptions!G10*Assumptions!G11*Assumptions!$C$17*1 -> 6000000 | I17: =Assumptions!G10*Assumptions!G11*Assumptions!$C$17*1 -> 6000000
B19: 3. Lead Fee Revenue ($/mo) | C19: P1 | D19: P2 | E19: P3 | F19: P4 | G19: P5 | H19: P6 | I19: P7
B20: A. Pilot (30 MAU) | C20: =Assumptions!C12*Assumptions!$C$18*0 -> 0 | D20: =Assumptions!C12*Assumptions!$C$18*1 -> 250 | E20: =Assumptions!C12*Assumptions!$C$18*1 -> 250 | F20: =Assumptions!C12*Assumptions!$C$18*1 -> 250 | G20: =Assumptions!C12*Assumptions!$C$18*1 -> 250 | H20: =Assumptions!C12*Assumptions!$C$18*1 -> 250 | I20: =Assumptions!C12*Assumptions!$C$18*1 -> 250
B21: B. Small (500 MAU) | C21: =Assumptions!D12*Assumptions!$C$18*0 -> 0 | D21: =Assumptions!D12*Assumptions!$C$18*1 -> 5000 | E21: =Assumptions!D12*Assumptions!$C$18*1 -> 5000 | F21: =Assumptions!D12*Assumptions!$C$18*1 -> 5000 | G21: =Assumptions!D12*Assumptions!$C$18*1 -> 5000 | H21: =Assumptions!D12*Assumptions!$C$18*1 -> 5000 | I21: =Assumptions!D12*Assumptions!$C$18*1 -> 5000
B22: C. Medium (4K MAU) | C22: =Assumptions!E12*Assumptions!$C$18*0 -> 0 | D22: =Assumptions!E12*Assumptions!$C$18*1 -> 50000 | E22: =Assumptions!E12*Assumptions!$C$18*1 -> 50000 | F22: =Assumptions!E12*Assumptions!$C$18*1 -> 50000 | G22: =Assumptions!E12*Assumptions!$C$18*1 -> 50000 | H22: =Assumptions!E12*Assumptions!$C$18*1 -> 50000 | I22: =Assumptions!E12*Assumptions!$C$18*1 -> 50000
B23: D. Large (20K MAU) | C23: =Assumptions!F12*Assumptions!$C$18*0 -> 0 | D23: =Assumptions!F12*Assumptions!$C$18*1 -> 250000 | E23: =Assumptions!F12*Assumptions!$C$18*1 -> 250000 | F23: =Assumptions!F12*Assumptions!$C$18*1 -> 250000 | G23: =Assumptions!F12*Assumptions!$C$18*1 -> 250000 | H23: =Assumptions!F12*Assumptions!$C$18*1 -> 250000 | I23: =Assumptions!F12*Assumptions!$C$18*1 -> 250000
B24: E. Viral (100K MAU) | C24: =Assumptions!G12*Assumptions!$C$18*0 -> 0 | D24: =Assumptions!G12*Assumptions!$C$18*1 -> 1250000 | E24: =Assumptions!G12*Assumptions!$C$18*1 -> 1250000 | F24: =Assumptions!G12*Assumptions!$C$18*1 -> 1250000 | G24: =Assumptions!G12*Assumptions!$C$18*1 -> 1250000 | H24: =Assumptions!G12*Assumptions!$C$18*1 -> 1250000 | I24: =Assumptions!G12*Assumptions!$C$18*1 -> 1250000
B26: TOTAL Monthly Revenue ($/mo) | C26: P1 | D26: P2 | E26: P3 | F26: P4 | G26: P5 | H26: P6 | I26: P7
B27: A. Pilot (30 MAU) | C27: =C6+C13+C20 -> 0 | D27: =D6+D13+D20 -> 250 | E27: =E6+E13+E20 -> 750 | F27: =F6+F13+F20 -> 1950 | G27: =G6+G13+G20 -> 1950 | H27: =H6+H13+H20 -> 1950 | I27: =I6+I13+I20 -> 1950
B28: B. Small (500 MAU) | C28: =C7+C14+C21 -> 0 | D28: =D7+D14+D21 -> 5000 | E28: =E7+E14+E21 -> 13000 | F28: =F7+F14+F21 -> 37000 | G28: =G7+G14+G21 -> 37000 | H28: =H7+H14+H21 -> 37000 | I28: =I7+I14+I21 -> 37000
B29: C. Medium (4K MAU) | C29: =C8+C15+C22 -> 0 | D29: =D8+D15+D22 -> 50000 | E29: =E8+E15+E22 -> 110000 | F29: =F8+F15+F22 -> 350000 | G29: =G8+G15+G22 -> 350000 | H29: =H8+H15+H22 -> 350000 | I29: =I8+I15+I22 -> 350000
B30: D. Large (20K MAU) | C30: =C9+C16+C23 -> 0 | D30: =D9+D16+D23 -> 250000 | E30: =E9+E16+E23 -> 550000 | F30: =F9+F16+F23 -> 1750000 | G30: =G9+G16+G23 -> 1750000 | H30: =H9+H16+H23 -> 1750000 | I30: =I9+I16+I23 -> 1750000
B31: E. Viral (100K MAU) | C31: =C10+C17+C24 -> 0 | D31: =D10+D17+D24 -> 1250000 | E31: =E10+E17+E24 -> 2650000 | F31: =F10+F17+F24 -> 8650000 | G31: =G10+G17+G24 -> 8650000 | H31: =H10+H17+H24 -> 8650000 | I31: =I10+I17+I24 -> 8650000
B33: Annualized Total Revenue ($/yr) | C33: P1 | D33: P2 | E33: P3 | F33: P4 | G33: P5 | H33: P6 | I33: P7
B34: A. Pilot (30 MAU) | C34: =C27*12 -> 0 | D34: =D27*12 -> 3000 | E34: =E27*12 -> 9000 | F34: =F27*12 -> 23400 | G34: =G27*12 -> 23400 | H34: =H27*12 -> 23400 | I34: =I27*12 -> 23400
B35: B. Small (500 MAU) | C35: =C28*12 -> 0 | D35: =D28*12 -> 60000 | E35: =E28*12 -> 156000 | F35: =F28*12 -> 444000 | G35: =G28*12 -> 444000 | H35: =H28*12 -> 444000 | I35: =I28*12 -> 444000
B36: C. Medium (4K MAU) | C36: =C29*12 -> 0 | D36: =D29*12 -> 600000 | E36: =E29*12 -> 1320000 | F36: =F29*12 -> 4200000 | G36: =G29*12 -> 4200000 | H36: =H29*12 -> 4200000 | I36: =I29*12 -> 4200000
B37: D. Large (20K MAU) | C37: =C30*12 -> 0 | D37: =D30*12 -> 3000000 | E37: =E30*12 -> 6600000 | F37: =F30*12 -> 21000000 | G37: =G30*12 -> 21000000 | H37: =H30*12 -> 21000000 | I37: =I30*12 -> 21000000
B38: E. Viral (100K MAU) | C38: =C31*12 -> 0 | D38: =D31*12 -> 15000000 | E38: =E31*12 -> 31800000 | F38: =F31*12 -> 103800000 | G38: =G31*12 -> 103800000 | H38: =H31*12 -> 103800000 | I38: =I31*12 -> 103800000
B40: Phase activation rules | C40: Lead fees: P2+ | Subscription: P3+ | Take rate: P4+

Sheet Net Margin
B2: Net Monthly Margin — Revenue minus Hosting Cost
B3: Green = profitable, Red = subsidizing. Excludes build cost, headcount, marketing.
B5: Net Monthly ($/mo) | C5: P1 | D5: P2 | E5: P3 | F5: P4 | G5: P5 | H5: P6 | I5: P7
B6: A. Pilot (30 MAU) | C6: =Revenue!C27-Costing!C6 -> -30 | D6: =Revenue!D27-Costing!D6 -> 215 | E6: =Revenue!E27-Costing!E6 -> 707 | F6: =Revenue!F27-Costing!F6 -> 1877 | G6: =Revenue!G27-Costing!G6 -> 1787 | H6: =Revenue!H27-Costing!H6 -> 1778 | I6: =Revenue!I27-Costing!I6 -> 1746
B7: B. Small (500 MAU) | C7: =Revenue!C28-Costing!C7 -> -324 | D7: =Revenue!D28-Costing!D7 -> 4616 | E7: =Revenue!E28-Costing!E7 -> 12496 | F7: =Revenue!F28-Costing!F7 -> 36342 | G7: =Revenue!G28-Costing!G7 -> 35988 | H7: =Revenue!H28-Costing!H7 -> 35892 | I7: =Revenue!I28-Costing!I7 -> 35685
B8: C. Medium (4K MAU) | C8: =Revenue!C29-Costing!C8 -> -1980 | D8: =Revenue!D29-Costing!D8 -> 47549 | E8: =Revenue!E29-Costing!E8 -> 106629 | F8: =Revenue!F29-Costing!F8 -> 345908 | G8: =Revenue!G29-Costing!G8 -> 344056 | H8: =Revenue!H29-Costing!H8 -> 343581 | I8: =Revenue!I29-Costing!I8 -> 342631
B9: D. Large (20K MAU) | C9: =Revenue!C30-Costing!C9 -> -7018 | D9: =Revenue!D30-Costing!D9 -> 240718 | E9: =Revenue!E30-Costing!E9 -> 536228 | F9: =Revenue!F30-Costing!F9 -> 1733710 | G9: =Revenue!G30-Costing!G9 -> 1727361 | H9: =Revenue!H30-Costing!H9 -> 1725631 | I9: =Revenue!I30-Costing!I9 -> 1722661
B10: E. Viral (100K MAU) | C10: =Revenue!C31-Costing!C10 -> -28426 | D10: =Revenue!D31-Costing!D10 -> 1210523 | E10: =Revenue!E31-Costing!E10 -> 2588323 | F10: =Revenue!F31-Costing!F10 -> 8577725 | G10: =Revenue!G31-Costing!G10 -> 8552725 | H10: =Revenue!H31-Costing!H10 -> 8545875 | I10: =Revenue!I31-Costing!I10 -> 8532475
B12: Gross Margin % (Net / Revenue) | C12: P1 | D12: P2 | E12: P3 | F12: P4 | G12: P5 | H12: P6 | I12: P7
B13: A. Pilot (30 MAU) | C13: =IFERROR((Revenue!C27-Costing!C6)/Revenue!C27,"") | D13: =IFERROR((Revenue!D27-Costing!D6)/Revenue!D27,"") -> 0.86 | E13: =IFERROR((Revenue!E27-Costing!E6)/Revenue!E27,"") -> 0.94266667 | F13: =IFERROR((Revenue!F27-Costing!F6)/Revenue!F27,"") -> 0.9625641 | G13: =IFERROR((Revenue!G27-Costing!G6)/Revenue!G27,"") -> 0.91641026 | H13: =IFERROR((Revenue!H27-Costing!H6)/Revenue!H27,"") -> 0.91179487 | I13: =IFERROR((Revenue!I27-Costing!I6)/Revenue!I27,"") -> 0.89538462
B14: B. Small (500 MAU) | C14: =IFERROR((Revenue!C28-Costing!C7)/Revenue!C28,"") | D14: =IFERROR((Revenue!D28-Costing!D7)/Revenue!D28,"") -> 0.9232 | E14: =IFERROR((Revenue!E28-Costing!E7)/Revenue!E28,"") -> 0.96123077 | F14: =IFERROR((Revenue!F28-Costing!F7)/Revenue!F28,"") -> 0.98221622 | G14: =IFERROR((Revenue!G28-Costing!G7)/Revenue!G28,"") -> 0.97264865 | H14: =IFERROR((Revenue!H28-Costing!H7)/Revenue!H28,"") -> 0.97005405 | I14: =IFERROR((Revenue!I28-Costing!I7)/Revenue!I28,"") -> 0.96445946
B15: C. Medium (4K MAU) | C15: =IFERROR((Revenue!C29-Costing!C8)/Revenue!C29,"") | D15: =IFERROR((Revenue!D29-Costing!D8)/Revenue!D29,"") -> 0.95098 | E15: =IFERROR((Revenue!E29-Costing!E8)/Revenue!E29,"") -> 0.96935455 | F15: =IFERROR((Revenue!F29-Costing!F8)/Revenue!F29,"") -> 0.98830857 | G15: =IFERROR((Revenue!G29-Costing!G8)/Revenue!G29,"") -> 0.98301714 | H15: =IFERROR((Revenue!H29-Costing!H8)/Revenue!H29,"") -> 0.98166 | I15: =IFERROR((Revenue!I29-Costing!I8)/Revenue!I29,"") -> 0.97894571
B16: D. Large (20K MAU) | C16: =IFERROR((Revenue!C30-Costing!C9)/Revenue!C30,"") | D16: =IFERROR((Revenue!D30-Costing!D9)/Revenue!D30,"") -> 0.962872 | E16: =IFERROR((Revenue!E30-Costing!E9)/Revenue!E30,"") -> 0.97496 | F16: =IFERROR((Revenue!F30-Costing!F9)/Revenue!F30,"") -> 0.99069143 | G16: =IFERROR((Revenue!G30-Costing!G9)/Revenue!G30,"") -> 0.98706343 | H16: =IFERROR((Revenue!H30-Costing!H9)/Revenue!H30,"") -> 0.98607486 | I16: =IFERROR((Revenue!I30-Costing!I9)/Revenue!I30,"") -> 0.98437771
B17: E. Viral (100K MAU) | C17: =IFERROR((Revenue!C31-Costing!C10)/Revenue!C31,"") | D17: =IFERROR((Revenue!D31-Costing!D10)/Revenue!D31,"") -> 0.9684184 | E17: =IFERROR((Revenue!E31-Costing!E10)/Revenue!E31,"") -> 0.97672566 | F17: =IFERROR((Revenue!F31-Costing!F10)/Revenue!F31,"") -> 0.99164451 | G17: =IFERROR((Revenue!G31-Costing!G10)/Revenue!G31,"") -> 0.98875434 | H17: =IFERROR((Revenue!H31-Costing!H10)/Revenue!H31,"") -> 0.98796243 | I17: =IFERROR((Revenue!I31-Costing!I10)/Revenue!I31,"") -> 0.98641329
B19: Annualized Net ($/yr) | C19: P1 | D19: P2 | E19: P3 | F19: P4 | G19: P5 | H19: P6 | I19: P7
B20: A. Pilot (30 MAU) | C20: =C6*12 -> -360 | D20: =D6*12 -> 2580 | E20: =E6*12 -> 8484 | F20: =F6*12 -> 22524 | G20: =G6*12 -> 21444 | H20: =H6*12 -> 21336 | I20: =I6*12 -> 20952
B21: B. Small (500 MAU) | C21: =C7*12 -> -3888 | D21: =D7*12 -> 55392 | E21: =E7*12 -> 149952 | F21: =F7*12 -> 436104 | G21: =G7*12 -> 431856 | H21: =H7*12 -> 430704 | I21: =I7*12 -> 428220
B22: C. Medium (4K MAU) | C22: =C8*12 -> -23760 | D22: =D8*12 -> 570588 | E22: =E8*12 -> 1279548 | F22: =F8*12 -> 4150896 | G22: =G8*12 -> 4128672 | H22: =H8*12 -> 4122972 | I22: =I8*12 -> 4111572
B23: D. Large (20K MAU) | C23: =C9*12 -> -84216 | D23: =D9*12 -> 2888616 | E23: =E9*12 -> 6434736 | F23: =F9*12 -> 20804520 | G23: =G9*12 -> 20728332 | H23: =H9*12 -> 20707572 | I23: =I9*12 -> 20671932
B24: E. Viral (100K MAU) | C24: =C10*12 -> -341112 | D24: =D10*12 -> 14526276 | E24: =E10*12 -> 31059876 | F24: =F10*12 -> 102932700 | G24: =G10*12 -> 102632700 | H24: =H10*12 -> 102550500 | I24: =I10*12 -> 102389700

Sheet Appendix
B2: Appendix — Abbreviations & Glossary
B3: All acronyms, codes, and shorthand used across the Assumptions, Costing, Revenue, Net Margin, and Summary sheets.
B5: Phases (per DBM-website-app-development roadmap)
B6: Abbreviation | C6: Full term | D6: Meaning in this workbook
B7: P1 | C7: Phase 1 — Find | D7: Find the required contact: search, directory, profile.
B8: P2 | C8: Phase 2 — Get Bids | D8: Bid forms, scope upload, AI scan of plans/specs.
B9: P3 | C9: Phase 3 — Compare | D9: Compare and finalize bids (side-by-side, negotiation).
B10: P4 | C10: Phase 4 — Sign | D10: Sign Contract / Agreement (e-sign, DocuSign).
B11: P5 | C11: Phase 5 — Execute | D11: Execute Contract: schedule, budget, RFI, payments, progress. Heaviest infra phase.
B12: P6 | C12: Phase 6 — Close | D12: Close Contract: punchlists, lien releases, final payment.
B13: P7 | C13: Phase 7 — Review | D13: Reviews / testimonials / lessons learnt.
B15: Customer tiers (rough load buckets)
B16: Abbreviation | C16: Full term | D16: Meaning in this workbook
B17: A. Pilot | C17: Pilot — 30 MAU | D17: Early design partners / beta. ~50 registered users, 5 paying pros.
B18: B. Small | C18: Small — 500 MAU | D18: First paying market. ~1K registered, 80 paying pros, 40 contracts/mo.
B19: C. Medium | C19: Medium — 4K MAU | D19: Regional traction. ~10K registered, 600 paying pros, 400 contracts/mo.
B20: D. Large | C20: Large — 20K MAU | D20: Multi-region scale. ~50K registered, 3K paying pros, 2K contracts/mo.
B21: E. Viral | C21: Viral — 100K MAU | D21: National scale. ~250K registered, 14K paying pros, 10K contracts/mo.
B23: Metrics & units
B24: Abbreviation | C24: Full term | D24: Meaning in this workbook
B25: MAU | C25: Monthly Active Users | D25: Distinct users with at least one session in the month. Drives most variable cost.
B26: Paying pros | C26: Paying professionals | D26: Contractors / pros on a paid subscription ($100/mo). Subset of MAU.
B27: Contract | C27: Brokered contract | D27: Signed agreement between homeowner and pro. Take-rate applies to contract value.
B28: Lead | C28: Qualified lead | D28: Homeowner request matched and delivered to a pro. Charged at $25/lead.
B29: Take rate | C29: Transaction take rate | D29: Platform fee as % of signed contract value. Set to 4% in Assumptions!C17.
B30: CAC | C30: Customer Acquisition Cost | D30: Marketing $ to acquire a paying customer. Excluded from this model.
B31: RFI | C31: Request for Information | D31: In-project clarification request between homeowner and pro. P5 feature.
B32: $/mo | C32: US dollars per month | D32: Monthly run-rate.
B33: $/yr | C33: US dollars per year | D33: Annualized run-rate (= monthly × 12).
B34: GM% | C34: Gross Margin percent | D34: (Revenue − Hosting Cost) / Revenue. Excludes headcount / build / marketing.
B36: Tech stack & vendors
B37: Abbreviation | C37: Full term | D37: Meaning in this workbook
B38: LLM | C38: Large Language Model | D38: AI model used for scope scans / chat (Anthropic Claude in this build).
B39: R2 | C39: Cloudflare R2 | D39: Object storage for uploads (PDFs, photos). S3-compatible, no egress fees.
B40: Postgres | C40: PostgreSQL | D40: Primary relational database (hosted on Render).
B41: Redis | C41: Redis | D41: In-memory cache / queue. Added in P5 for jobs and rate limits.
B42: Render | C42: Render.com | D42: Chosen hosting platform — managed Web Services, Postgres, cron, disks.
B43: AWS | C43: Amazon Web Services | D43: Alternative hosting (Fargate / RDS / S3). Compared in HOSTING_COSTS_CLOUDS.md.
B44: GCP | C44: Google Cloud Platform | D44: Alternative hosting (Cloud Run / Cloud SQL / GCS). Same doc.
B45: CDN | C45: Content Delivery Network | D45: Edge caching for static assets (Cloudflare / Render CDN).
...
